{"version":3,"sources":["throw3.es6"],"names":[],"mappings":";;;;;;;;;;;;;;;;;;;;;;;AAAA;;;AAGA,QAAI,+BAAI,SAAJ,CAAI;AAAA;AAAA;AAAA;AAAA;AAAA,6BACG,IADH;AAAA;AAAA;AAAA;;AAAA;AAAA;;AAAA;AAGA,gCAAQ,GAAR,CAAY,MAAZ,EAAoB,CAApB;AAHA;AAAA;;AAAA;AAAA;AAAA;AAAA;AAAA;AAAA,WAAJ,CAAI;AAAA,KAAJ,CAAJ;;AAOA,QAAI,IAAI,GAAR;AACA,MAAE,IAAF;;AAEA,QAAI;AACA,UAAE,KAAF,CAAQ,GAAR;AACA,UAAE,KAAF,CAAQ,GAAR;AACH,KAHD,CAGE,OAAO,CAAP,EAAU;AACR,gBAAQ,GAAR,CAAY,MAAZ,EAAoB,CAApB;AACH;AACD","file":"throw3.js","sourcesContent":["/**\r\n * 如果Generator函数内部没有部署try...catch代码块，那么throw方法抛出的错误，将被外部try...catch代码块捕获。\r\n */\r\nvar g = function* () {\r\n    while (true) {\r\n        yield;\r\n        console.log('内部捕获', e);\r\n    }\r\n};\r\n\r\nvar i = g();\r\ni.next();\r\n\r\ntry {\r\n    i.throw('a');\r\n    i.throw('b');\r\n} catch (e) {\r\n    console.log('外部捕获', e);\r\n}\r\n// 外部捕获 a"]}