{"version":3,"sources":["throw9.es6"],"names":[],"mappings":";;;;;;;;;;;;;;;;;;;;;;;6CAIU,G;;AAJV;;;;AAIA,aAAU,GAAV;AAAA;AAAA;AAAA;AAAA;AAAA;AAAA;AAAA,+BACkB,CADlB;;AAAA;AACQ,yBADR;AAEQ,yBAFR,GAEY,EAAE,WAAF,EAFZ;AAAA;AAAA,+BAGU,CAHV;;AAAA;AAAA;AAAA;AAAA;AAAA;AAAA;AAAA;;AAMA,QAAI,KAAK,KAAT;;AAEA,OAAG,IAAH,G,CAAW;;AAEX,QAAI;AACA,WAAG,IAAH,CAAQ,EAAR;AACH,KAFD,CAEE,OAAO,GAAP,EAAY;AACV,gBAAQ,GAAR,CAAY,IAAI,OAAhB;AACH;AACD","file":"throw9.js","sourcesContent":["/**\r\n * Generator函数体外抛出的错误，可以在函数体内捕获；反过来，Generator函数体内抛出的错误，也可以被函数体外的catch捕获。\r\n */\r\n\r\nfunction *foo() {\r\n    var x = yield 3;\r\n    var y = x.toUpperCase();\r\n    yield y;\r\n}\r\n\r\nvar it = foo();\r\n\r\nit.next(); // { value:3, done:false }\r\n\r\ntry {\r\n    it.next(42);\r\n} catch (err) {\r\n    console.log(err.message);\r\n}\r\n// 上面代码中，第二个next方法向函数体内传入一个参数42，数值是没有toUpperCase方法的，所以会抛出一个TypeError错误，被函数体外的catch捕获。"]}